I'm sorry, but an uncaught exception occurred.

While running game code:
  File "game/script.rpy", line 588, in script
    pavel "Добрый вечер, если не ошибаюсь наш тираж превысил 200 млн копий"
Exception: Sayer 'pavel' is not defined.

-- Full Traceback ------------------------------------------------------------

Full traceback:
  File "game/script.rpy", line 588, in script
    pavel "Добрый вечер, если не ошибаюсь наш тираж превысил 200 млн копий"
  File "C:\Users\admin\Downloads\renpy-8.0.3-sdk\renpy\ast.py", line 881, in execute
    who = eval_who(self.who, self.who_fast)
  File "C:\Users\admin\Downloads\renpy-8.0.3-sdk\renpy\ast.py", line 774, in eval_who
    raise Exception("Sayer '%s' is not defined." % who)
Exception: Sayer 'pavel' is not defined.

Windows-10-10.0.19044 AMD64
Ren'Py 8.0.3.22090809
SaveGameIndustry 1.0
Thu Dec  1 20:05:50 2022
